Workbook

Sheet 01_Customer_Tracker
A1: customer_id | B1: company_name | C1: industry | D1: employee_count | E1: onboarding_start_date | F1: target_closure_date | G1: current_stage | H1: status | I1: total_tasks | J1: completed_tasks | K1: completion_pct | L1: blocked_tasks | M1: days_remaining | N1: sla_status | P1: Reference Date: | Q1: 46283
A2: C001 | B2: Everest Systems | C2: EdTech | D2: 20 | E2: 46245 | F2: 46309 | G2: Approval | H2: Blocked | I2: =COUNTIF('04_Task_Pipeline'!$B:$B,A2) | J2: =COUNTIFS('04_Task_Pipeline'!$B:$B,A2,'04_Task_Pipeline'!$F:$F,"Completed") | K2: =IF(I2=0,0,J2/I2) | L2: =COUNTIFS('04_Task_Pipeline'!$B:$B,A2,'04_Task_Pipeline'!$F:$F,"Blocked") | M2: =F2-$Q$1 | N2: =IF(G2="Completed","Completed",IF(L2>0,"Blocked",IF(M2<0,"SLA Breach",IF(AND(M2<=7,K2<0.75),"At Risk",IF(AND(M2<=14,K2<0.5),"At Risk","On Track")))))
A3: C002 | B3: Anchor Works | C3: Hospitality | D3: 32 | E3: 46227 | F3: 46288 | G3: Documents | H3: At Risk | I3: =COUNTIF('04_Task_Pipeline'!$B:$B,A3) | J3: =COUNTIFS('04_Task_Pipeline'!$B:$B,A3,'04_Task_Pipeline'!$F:$F,"Completed") | K3: =IF(I3=0,0,J3/I3) | L3: =COUNTIFS('04_Task_Pipeline'!$B:$B,A3,'04_Task_Pipeline'!$F:$F,"Blocked") | M3: =F3-$Q$1 | N3: =IF(G3="Completed","Completed",IF(L3>0,"Blocked",IF(M3<0,"SLA Breach",IF(AND(M3<=7,K3<0.75),"At Risk",IF(AND(M3<=14,K3<0.5),"At Risk","On Track")))))
A4: C003 | B4: Zenith Solutions | C4: E-commerce | D4: 38 | E4: 46223 | F4: 46278 | G4: Completed | H4: Completed | I4: =COUNTIF('04_Task_Pipeline'!$B:$B,A4) | J4: =COUNTIFS('04_Task_Pipeline'!$B:$B,A4,'04_Task_Pipeline'!$F:$F,"Completed") | K4: =IF(I4=0,0,J4/I4) | L4: =COUNTIFS('04_Task_Pipeline'!$B:$B,A4,'04_Task_Pipeline'!$F:$F,"Blocked") | M4: =F4-$Q$1 | N4: =IF(G4="Completed","Completed",IF(L4>0,"Blocked",IF(M4<0,"SLA Breach",IF(AND(M4<=7,K4<0.75),"At Risk",IF(AND(M4<=14,K4<0.5),"At Risk","On Track")))))
A5: C004 | B5: Bridge Industries | C5: Logistics | D5: 12 | E5: 46268 | F5: 46320 | G5: Documents | H5: On Track | I5: =COUNTIF('04_Task_Pipeline'!$B:$B,A5) | J5: =COUNTIFS('04_Task_Pipeline'!$B:$B,A5,'04_Task_Pipeline'!$F:$F,"Completed") | K5: =IF(I5=0,0,J5/I5) | L5: =COUNTIFS('04_Task_Pipeline'!$B:$B,A5,'04_Task_Pipeline'!$F:$F,"Blocked") | M5: =F5-$Q$1 | N5: =IF(G5="Completed","Completed",IF(L5>0,"Blocked",IF(M5<0,"SLA Breach",IF(AND(M5<=7,K5<0.75),"At Risk",IF(AND(M5<=14,K5<0.5),"At Risk","On Track")))))
A6: C005 | B6: Nimbus Group | C6: E-commerce | D6: 32 | E6: 46228 | F6: 46272 | G6: Completed | H6: Completed | I6: =COUNTIF('04_Task_Pipeline'!$B:$B,A6) | J6: =COUNTIFS('04_Task_Pipeline'!$B:$B,A6,'04_Task_Pipeline'!$F:$F,"Completed") | K6: =IF(I6=0,0,J6/I6) | L6: =COUNTIFS('04_Task_Pipeline'!$B:$B,A6,'04_Task_Pipeline'!$F:$F,"Blocked") | M6: =F6-$Q$1 | N6: =IF(G6="Completed","Completed",IF(L6>0,"Blocked",IF(M6<0,"SLA Breach",IF(AND(M6<=7,K6<0.75),"At Risk",IF(AND(M6<=14,K6<0.5),"At Risk","On Track")))))
A7: C006 | B7: Wavelength Works | C7: EdTech | D7: 32 | E7: 46224 | F7: 46261 | G7: Payroll Setup | H7: Blocked | I7: =COUNTIF('04_Task_Pipeline'!$B:$B,A7) | J7: =COUNTIFS('04_Task_Pipeline'!$B:$B,A7,'04_Task_Pipeline'!$F:$F,"Completed") | K7: =IF(I7=0,0,J7/I7) | L7: =COUNTIFS('04_Task_Pipeline'!$B:$B,A7,'04_Task_Pipeline'!$F:$F,"Blocked") | M7: =F7-$Q$1 | N7: =IF(G7="Completed","Completed",IF(L7>0,"Blocked",IF(M7<0,"SLA Breach",IF(AND(M7<=7,K7<0.75),"At Risk",IF(AND(M7<=14,K7<0.5),"At Risk","On Track")))))
A8: C007 | B8: Bridge Technologies | C8: Hospitality | D8: 29 | E8: 46214 | F8: 46273 | G8: Completed | H8: Completed | I8: =COUNTIF('04_Task_Pipeline'!$B:$B,A8) | J8: =COUNTIFS('04_Task_Pipeline'!$B:$B,A8,'04_Task_Pipeline'!$F:$F,"Completed") | K8: =IF(I8=0,0,J8/I8) | L8: =COUNTIFS('04_Task_Pipeline'!$B:$B,A8,'04_Task_Pipeline'!$F:$F,"Blocked") | M8: =F8-$Q$1 | N8: =IF(G8="Completed","Completed",IF(L8>0,"Blocked",IF(M8<0,"SLA Breach",IF(AND(M8<=7,K8<0.75),"At Risk",IF(AND(M8<=14,K8<0.5),"At Risk","On Track")))))
A9: C008 | B9: Union Solutions | C9: Media & Entertainment | D9: 17 | E9: 46269 | F9: 46317 | G9: Employee Upload | H9: On Track | I9: =COUNTIF('04_Task_Pipeline'!$B:$B,A9) | J9: =COUNTIFS('04_Task_Pipeline'!$B:$B,A9,'04_Task_Pipeline'!$F:$F,"Completed") | K9: =IF(I9=0,0,J9/I9) | L9: =COUNTIFS('04_Task_Pipeline'!$B:$B,A9,'04_Task_Pipeline'!$F:$F,"Blocked") | M9: =F9-$Q$1 | N9: =IF(G9="Completed","Completed",IF(L9>0,"Blocked",IF(M9<0,"SLA Breach",IF(AND(M9<=7,K9<0.75),"At Risk",IF(AND(M9<=14,K9<0.5),"At Risk","On Track")))))
A10: C009 | B10: Ironclad Industries | C10: Healthcare | D10: 12 | E10: 46237 | F10: 46293 | G10: Payroll Setup | H10: On Track | I10: =COUNTIF('04_Task_Pipeline'!$B:$B,A10) | J10: =COUNTIFS('04_Task_Pipeline'!$B:$B,A10,'04_Task_Pipeline'!$F:$F,"Completed") | K10: =IF(I10=0,0,J10/I10) | L10: =COUNTIFS('04_Task_Pipeline'!$B:$B,A10,'04_Task_Pipeline'!$F:$F,"Blocked") | M10: =F10-$Q$1 | N10: =IF(G10="Completed","Completed",IF(L10>0,"Blocked",IF(M10<0,"SLA Breach",IF(AND(M10<=7,K10<0.75),"At Risk",IF(AND(M10<=14,K10<0.5),"At Risk","On Track")))))
A11: C010 | B11: Fjord Group | C11: IT Services | D11: 15 | E11: 46224 | F11: 46287 | G11: Completed | H11: Completed | I11: =COUNTIF('04_Task_Pipeline'!$B:$B,A11) | J11: =COUNTIFS('04_Task_Pipeline'!$B:$B,A11,'04_Task_Pipeline'!$F:$F,"Completed") | K11: =IF(I11=0,0,J11/I11) | L11: =COUNTIFS('04_Task_Pipeline'!$B:$B,A11,'04_Task_Pipeline'!$F:$F,"Blocked") | M11: =F11-$Q$1 | N11: =IF(G11="Completed","Completed",IF(L11>0,"Blocked",IF(M11<0,"SLA Breach",IF(AND(M11<=7,K11<0.75),"At Risk",IF(AND(M11<=14,K11<0.5),"At Risk","On Track")))))
A12: C011 | B12: Quill Industries | C12: Retail | D12: 14 | E12: 46258 | F12: 46315 | G12: Documents | H12: On Track | I12: =COUNTIF('04_Task_Pipeline'!$B:$B,A12) | J12: =COUNTIFS('04_Task_Pipeline'!$B:$B,A12,'04_Task_Pipeline'!$F:$F,"Completed") | K12: =IF(I12=0,0,J12/I12) | L12: =COUNTIFS('04_Task_Pipeline'!$B:$B,A12,'04_Task_Pipeline'!$F:$F,"Blocked") | M12: =F12-$Q$1 | N12: =IF(G12="Completed","Completed",IF(L12>0,"Blocked",IF(M12<0,"SLA Breach",IF(AND(M12<=7,K12<0.75),"At Risk",IF(AND(M12<=14,K12<0.5),"At Risk","On Track")))))
A13: C012 | B13: Onyx Services | C13: Hospitality | D13: 33 | E13: 46223 | F13: 46279 | G13: Approval | H13: At Risk | I13: =COUNTIF('04_Task_Pipeline'!$B:$B,A13) | J13: =COUNTIFS('04_Task_Pipeline'!$B:$B,A13,'04_Task_Pipeline'!$F:$F,"Completed") | K13: =IF(I13=0,0,J13/I13) | L13: =COUNTIFS('04_Task_Pipeline'!$B:$B,A13,'04_Task_Pipeline'!$F:$F,"Blocked") | M13: =F13-$Q$1 | N13: =IF(G13="Completed","Completed",IF(L13>0,"Blocked",IF(M13<0,"SLA Breach",IF(AND(M13<=7,K13<0.75),"At Risk",IF(AND(M13<=14,K13<0.5),"At Risk","On Track")))))
... A51: C050 | B51: Orbit Systems | C51: Manufacturing | D51: 33 | E51: 46243 | F51: 46282 | G51: Customer Review | H51: At Risk | I51: =COUNTIF('04_Task_Pipeline'!$B:$B,A51) | J51: =COUNTIFS('04_Task_Pipeline'!$B:$B,A51,'04_Task_Pipeline'!$F:$F,"Completed") | K51: =IF(I51=0,0,J51/I51) | L51: =COUNTIFS('04_Task_Pipeline'!$B:$B,A51,'04_Task_Pipeline'!$F:$F,"Blocked") | M51: =F51-$Q$1 | N51: =IF(G51="Completed","Completed",IF(L51>0,"Blocked",IF(M51<0,"SLA Breach",IF(AND(M51<=7,K51<0.75),"At Risk",IF(AND(M51<=14,K51<0.5),"At Risk","On Track")))))

Sheet 02_Employee_Master
A1: employee_id | B1: customer_id | C1: name | D1: department | E1: basic_pay | F1: hra | G1: special_allowance | H1: overtime_pay | I1: bonus | J1: bank_account_no | K1: pan_number | L1: uan_number | M1: attendance_days | N1: lop_days | O1: customer_name
A2: E001 | B2: C041 | C2: Amit Chatterjee | D2: HR | E2: 34174 | F2: 13670 | G2: 10053 | H2: 1835 | I2: 0 | J2: 193327551503 | K2: XEOIC4843Q | L2: 959814485368 | M2: 29 | N2: 0 | O2: =IFERROR(INDEX('01_Customer_Tracker'!$B:$B,MATCH(B2,'01_Customer_Tracker'!$A:$A,0)),"")
A3: E002 | B3: C032 | C3: Kabir Gupta | D3: Engineering | E3: 85351 | F3: 34140 | G3: 11577 | H3: 5047 | I3: 618 | J3: 253605945389 | K3: OBZLG5644U | L3: 145864434317 | M3: 26 | N3: 1 | O3: =IFERROR(INDEX('01_Customer_Tracker'!$B:$B,MATCH(B3,'01_Customer_Tracker'!$A:$A,0)),"")
A4: E003 | B4: C046 | C4: Myra Menon | D4: Engineering | E4: 82334 | F4: 32934 | G4: 8830 | H4: 2958 | I4: 1242 | J4: 400184519405 | K4: FKDAH2008K | L4: 101109756260 | M4: 30 | N4: 0 | O4: =IFERROR(INDEX('01_Customer_Tracker'!$B:$B,MATCH(B4,'01_Customer_Tracker'!$A:$A,0)),"")
A5: E004 | B5: C032 | C5: Ananya Kapoor | D5: Engineering | E5: 39982 | F5: 15993 | G5: 5806 | H5: 1379 | I5: 0 | J5: 842791669151 | K5: NGFIP3182X | L5: 714932521892 | M5: 27 | N5: 2 | O5: =IFERROR(INDEX('01_Customer_Tracker'!$B:$B,MATCH(B5,'01_Customer_Tracker'!$A:$A,0)),"")
A6: E005 | B6: C048 | C6: Aadhya Iyer | D6: Marketing | E6: 51197 | F6: 20479 | G6: 2009 | H6: 2026 | I6: 0 | J6: 158949471441 | K6: LPBID1185X | L6: 108333803639 | M6: 30 | N6: 0 | O6: =IFERROR(INDEX('01_Customer_Tracker'!$B:$B,MATCH(B6,'01_Customer_Tracker'!$A:$A,0)),"")
A7: E006 | B7: C038 | C7: Reyansh Gupta | D7: HR | E7: 61511 | F7: 24604 | G7: 6492 | H7: 1188 | I7: 0 | J7: 594293428937 | K7: RWMAH8679N | M7: 28 | N7: 0 | O7: =IFERROR(INDEX('01_Customer_Tracker'!$B:$B,MATCH(B7,'01_Customer_Tracker'!$A:$A,0)),"")
A8: E007 | B8: C030 | C8: Amit Agarwal | D8: Operations | E8: 34069 | F8: 13628 | G8: 4108 | H8: 2503 | I8: 0 | J8: 607390209789 | K8: XZCJT8317D | L8: 819292170016 | M8: 26 | N8: 0 | O8: =IFERROR(INDEX('01_Customer_Tracker'!$B:$B,MATCH(B8,'01_Customer_Tracker'!$A:$A,0)),"")
A9: E008 | B9: C005 | C9: Diya Iyer | D9: Finance | E9: 46051 | F9: 18420 | G9: 8174 | H9: 1170 | I9: 5171 | K9: AJASE6931S | L9: 737282112114 | M9: 26 | N9: 0 | O9: =IFERROR(INDEX('01_Customer_Tracker'!$B:$B,MATCH(B9,'01_Customer_Tracker'!$A:$A,0)),"")
A10: E009 | B10: C012 | C10: Priya Gupta | D10: Marketing | E10: 26095 | F10: 10438 | G10: 7735 | H10: 493 | I10: 756 | J10: 696164472659 | K10: BEUND9924G | L10: 114921821707 | M10: 24 | N10: 0 | O10: =IFERROR(INDEX('01_Customer_Tracker'!$B:$B,MATCH(B10,'01_Customer_Tracker'!$A:$A,0)),"")
A11: E191 | B11: C030 | C11: Aryan Chatterjee | D11: Operations | E11: 24518 | F11: 9807 | G11: 7513 | H11: 1759 | I11: 0 | J11: 540838408979 | K11: EQEHS1454L | L11: 365279673882 | M11: 28 | N11: 0 | O11: =IFERROR(INDEX('01_Customer_Tracker'!$B:$B,MATCH(B11,'01_Customer_Tracker'!$A:$A,0)),"")
A12: E011 | B12: C009 | C12: Amit Pillai | D12: Sales | E12: 16362 | F12: 6545 | G12: 2045 | H12: 779 | I12: 5084 | J12: 261127861495 | K12: WQPEO5726K | L12: 709858687239 | M12: 27 | N12: 0 | O12: =IFERROR(INDEX('01_Customer_Tracker'!$B:$B,MATCH(B12,'01_Customer_Tracker'!$A:$A,0)),"")
A13: E012 | B13: C031 | C13: Priya Nair | D13: Support | E13: 68821 | F13: 27528 | G13: 11825 | H13: 824 | I13: 0 | J13: 22345179161 | K13: KAUJN4851K | L13: 184664766780 | M13: 29 | N13: 0 | O13: =IFERROR(INDEX('01_Customer_Tracker'!$B:$B,MATCH(B13,'01_Customer_Tracker'!$A:$A,0)),"")
A14: E013 | B14: C048 | C14: Karan Reddy | D14: HR | E14: 50159 | F14: 20064 | G14: 3068 | H14: 1442 | I14: 5769 | J14: 207546572970 | L14: 760145414105 | M14: 27 | N14: 0 | O14: =IFERROR(INDEX('01_Customer_Tracker'!$B:$B,MATCH(B14,'01_Customer_Tracker'!$A:$A,0)),"")
A15: E014 | B15: C005 | C15: Om Singh | D15: Operations | E15: 53776 | F15: 21510 | G15: 2432 | H15: 3190 | I15: 0 | J15: 785130528725 | K15: YOLCU9134S | L15: 818287692235 | M15: 30 | N15: 0 | O15: =IFERROR(INDEX('01_Customer_Tracker'!$B:$B,MATCH(B15,'01_Customer_Tracker'!$A:$A,0)),"")
A16: E015 | B16: C003 | C16: Ishaan Mehta | D16: Support | E16: 49185 | F16: 19674 | G16: 1742 | H16: 827 | I16: 0 | J16: 722119408353 | K16: ZYXQK6639I | L16: 647867016007 | M16: 27 | N16: 0 | O16: =IFERROR(INDEX('01_Customer_Tracker'!$B:$B,MATCH(B16,'01_Customer_Tracker'!$A:$A,0)),"")
A17: E016 | B17: C032 | C17: Aryan Sharma | D17: HR | E17: 58183 | F17: 23273 | G17: 11321 | H17: 2346 | I17: 2805 | J17: 383433923053 | K17: JKTDI2465I | L17: 405529978787 | M17: 28 | N17: 0 | O17: =IFERROR(INDEX('01_Customer_Tracker'!$B:$B,MATCH(B17,'01_Customer_Tracker'!$A:$A,0)),"")
A18: E017 | B18: C048 | C18: Priya Iyer | D18: Sales | E18: 22419 | F18: 8968 | G18: 6465 | H18: 1351 | I18: 0 | J18: 285332223302 | K18: MFZEM5697B | L18: 333495855868 | M18: 27 | N18: 0 | O18: =IFERROR(INDEX('01_Customer_Tracker'!$B:$B,MATCH(B18,'01_Customer_Tracker'!$A:$A,0)),"")
A19: E018 | B19: C026 | C19: Riya Verma | D19: Marketing | E19: 33356 | F19: 13342 | G19: 8351 | H19: 1796 | I19: 2973 | J19: 259911927643 | K19: DHITH8889U | L19: 986111747424 | M19: 30 | N19: 0 | O19: =IFERROR(INDEX('01_Customer_Tracker'!$B:$B,MATCH(B19,'01_Customer_Tracker'!$A:$A,0)),"")
A20: E019 | B20: C031 | C20: Kiara Chauhan | D20: HR | E20: 20386 | F20: 8154 | G20: 5806 | H20: 224 | I20: 1334 | J20: 106008109818 | L20: 248780191030 | M20: 24 | N20: 0 | O20: =IFERROR(INDEX('01_Customer_Tracker'!$B:$B,MATCH(B20,'01_Customer_Tracker'!$A:$A,0)),"")
A21: E020 | B21: C039 | C21: Arjun Agarwal | D21: Operations | E21: 58817 | F21: 23527 | G21: 7002 | H21: 3458 | I21: 5087 | J21: 410806414781 | K21: JCTAU1388F | L21: 947384971063 | M21: 26 | N21: 0 | O21: =IFERROR(INDEX('01_Customer_Tracker'!$B:$B,MATCH(B21,'01_Customer_Tracker'!$A:$A,0)),"")
A22: E021 | B22: C015 | C22: Arjun Rao | D22: Engineering | E22: 43867 | F22: 17547 | G22: 4277 | H22: 624 | I22: 5078 | J22: 419432251996 | K22: BLEGW7391D | L22: 887117625869 | M22: 29 | N22: 0 | O22: =IFERROR(INDEX('01_Customer_Tracker'!$B:$B,MATCH(B22,'01_Customer_Tracker'!$A:$A,0)),"")
A23: E022 | B23: C043 | C23: Dhruv Joshi | D23: Support | E23: 33630 | F23: 13452 | G23: 4997 | H23: 658 | I23: 219 | J23: 889108940318 | K23: YAUIN3539M | L23: 576771099563 | M23: 26 | N23: 0 | O23: =IFERROR(INDEX('01_Customer_Tracker'!$B:$B,MATCH(B23,'01_Customer_Tracker'!$A:$A,0)),"")
A24: E023 | B24: C021 | C24: Dhruv Singh | D24: Engineering | E24: 41978 | F24: 16791 | G24: 2819 | H24: 612 | I24: 0 | J24: 953673469655 | K24: YDEJO9637F | L24: 327866145513 | M24: 30 | N24: 0 | O24: =IFERROR(INDEX('01_Customer_Tracker'!$B:$B,MATCH(B24,'01_Customer_Tracker'!$A:$A,0)),"")
A25: E024 | B25: C046 | C25: Reyansh Kulkarni | D25: Engineering | E25: 39114 | F25: 15646 | G25: 11111 | H25: 1902 | I25: 0 | J25: 406446732792 | K25: NNREV9896D | L25: 767453169457 | M25: 29 | N25: 0 | O25: =IFERROR(INDEX('01_Customer_Tracker'!$B:$B,MATCH(B25,'01_Customer_Tracker'!$A:$A,0)),"")
A26: E025 | B26: C043 | C26: Tanvi Reddy | D26: Support | E26: 84049 | F26: 33620 | G26: 8659 | H26: 2295 | I26: 5590 | J26: 796512460190 | K26: IRQBT6735U | L26: 290759149972 | M26: 25 | N26: 0 | O26: =IFERROR(INDEX('01_Customer_Tracker'!$B:$B,MATCH(B26,'01_Customer_Tracker'!$A:$A,0)),"")
A27: E026 | B27: C022 | C27: Varun Nair | D27: HR | E27: 71546 | F27: 28618 | G27: 1524 | H27: 3162 | I27: 5960 | J27: 71442475474 | K27: KLUDL2370U | L27: 453634652412 | M27: 28 | N27: 0 | O27: =IFERROR(INDEX('01_Customer_Tracker'!$B:$B,MATCH(B27,'01_Customer_Tracker'!$A:$A,0)),"")
A28: E027 | B28: C047 | C28: Om Patel | D28: Operations | E28: 69463 | F28: 27785 | G28: 9055 | H28: 2562 | I28: 0 | J28: 603698403148 | K28: BMPYN4084O | L28: 710284654791 | M28: 25 | N28: 0 | O28: =IFERROR(INDEX('01_Customer_Tracker'!$B:$B,MATCH(B28,'01_Customer_Tracker'!$A:$A,0)),"")
A29: E028 | B29: C033 | C29: Aryan Sharma | D29: Marketing | E29: 48722 | F29: 19489 | G29: 4541 | H29: 3478 | I29: 0 | J29: 991889639331 | K29: LNTRE3722J | L29: 429701939700 | M29: 30 | N29: 0 | O29: =IFERROR(INDEX('01_Customer_Tracker'!$B:$B,MATCH(B29,'01_Customer_Tracker'!$A:$A,0)),"")
A30: E029 | B30: C039 | C30: Myra Mehta | D30: Marketing | E30: 57136 | F30: 22854 | G30: 3069 | H30: 3289 | I30: 0 | J30: 908015463639 | K30: IKEQK4080S | L30: 496045097409 | M30: 26 | N30: 2 | O30: =IFERROR(INDEX('01_Customer_Tracker'!$B:$B,MATCH(B30,'01_Customer_Tracker'!$A:$A,0)),"")
A31: E030 | B31: C035 | C31: Vihaan Patel | D31: HR | E31: 24847 | F31: 9939 | G31: 8382 | H31: 1456 | I31: 3977 | J31: 333281374244 | K31: UFEUY8744T | L31: 701064242962 | M31: 25 | N31: 2 | O31: =IFERROR(INDEX('01_Customer_Tracker'!$B:$B,MATCH(B31,'01_Customer_Tracker'!$A:$A,0)),"")
A32: E031 | B32: C002 | C32: Diya Menon | D32: Engineering | E32: 36040 | F32: 14416 | G32: 4476 | H32: 810 | I32: 0 | J32: 210497183844 | K32: RYOOS7921Y | L32: 649054434597 | M32: 29 | N32: 0 | O32: =IFERROR(INDEX('01_Customer_Tracker'!$B:$B,MATCH(B32,'01_Customer_Tracker'!$A:$A,0)),"")
... A69: E068 | B69: C006 | C69: Rohan Kulkarni | D69: Sales | E69: 68633 | F69: 27453 | G69: 11335 | H69: 4188 | I69: 1127 | J69: 502671225341 | K69: NNANY4929H | L69: 537652551403 | M69: 30 | N69: 0 | O69: =IFERROR(INDEX('01_Customer_Tracker'!$B:$B,MATCH(B69,'01_Customer_Tracker'!$A:$A,0)),"")
A70: E069 | B70: C048 | C70: Varun Mehta | D70: Marketing | E70: 20011 | F70: 8004 | G70: 9206 | H70: 948 | I70: 4318 | K70: QPZAM5448X | L70: 528005055909 | M70: 29 | N70: 0 | O70: =IFERROR(INDEX('01_Customer_Tracker'!$B:$B,MATCH(B70,'01_Customer_Tracker'!$A:$A,0)),"")
A71: E070 | B71: C010 | C71: Aditya Rao | D71: HR | E71: 71070 | F71: 28428 | G71: 9708 | H71: 5135 | I71: 0 | J71: 857666713757 | K71: LUQHJ4914R | L71: 704668769751 | M71: 30 | N71: 0 | O71: =IFERROR(INDEX('01_Customer_Tracker'!$B:$B,MATCH(B71,'01_Customer_Tracker'!$A:$A,0)),"")
A72: E071 | B72: C023 | C72: Rahul Chatterjee | D72: Operations | E72: 62182 | F72: 24873 | G72: 10027 | H72: 40418 | I72: 0 | J72: 465112369808 | K72: NNFPT4146D | L72: 278725297177 | M72: 26 | N72: 0 | O72: =IFERROR(INDEX('01_Customer_Tracker'!$B:$B,MATCH(B72,'01_Customer_Tracker'!$A:$A,0)),"")
A73: E072 | B73: C034 | C73: Om Iyer | D73: Marketing | E73: 69933 | F73: 27973 | G73: 4362 | H73: 3150 | I73: 0 | J73: 162878857141 | K73: CHFKH3952N | L73: 894543009429 | M73: 29 | N73: 0 | O73: =IFERROR(INDEX('01_Customer_Tracker'!$B:$B,MATCH(B73,'01_Customer_Tracker'!$A:$A,0)),"")
A74: E073 | B74: C041 | C74: Sneha Pillai | D74: Sales | E74: 71345 | F74: 28538 | G74: 5255 | H74: 4494 | I74: 2870 | J74: 280695405105 | K74: GIJDS5951V | L74: 162938468329 | M74: 28 | N74: 0 | O74: =IFERROR(INDEX('01_Customer_Tracker'!$B:$B,MATCH(B74,'01_Customer_Tracker'!$A:$A,0)),"")
A75: E074 | B75: C034 | C75: Rohan Menon | D75: HR | E75: 71099 | F75: 28440 | G75: 2644 | H75: 4635 | I75: 0 | J75: 822351511812 | K75: HGIJE2587G | L75: 452854020173 | M75: 27 | N75: 2 | O75: =IFERROR(INDEX('01_Customer_Tracker'!$B:$B,MATCH(B75,'01_Customer_Tracker'!$A:$A,0)),"")
A76: E075 | B76: C021 | C76: Sneha Reddy | D76: Operations | E76: 28766 | F76: 11506 | G76: 4364 | H76: 841 | I76: 0 | J76: 309934982548 | K76: DWJXG5853T | L76: 937003012618 | M76: 26 | N76: 0 | O76: =IFERROR(INDEX('01_Customer_Tracker'!$B:$B,MATCH(B76,'01_Customer_Tracker'!$A:$A,0)),"")
...

Sheet 03_Payroll_Register
A1: employee_id | B1: customer_id | C1: gross_earnings | D1: expected_net_pay | E1: processed_net_pay | F1: pf_deduction | G1: esi_deduction | H1: pt_deduction | I1: tds_deduction | J1: variance | K1: department | L1: bank_account_no
A2: E001 | B2: C041 | C2: 59732 | D2: 55431 | E2: 55431 | F2: 4101 | G2: 0 | H2: 200 | I2: 0 | J2: 0 | K2: =IFERROR(INDEX('02_Employee_Master'!$D:$D,MATCH(A2,'02_Employee_Master'!$A:$A,0)),"") | L2: =IFERROR(INDEX('02_Employee_Master'!$J:$J,MATCH(A2,'02_Employee_Master'!$A:$A,0)),"")
A3: E002 | B3: C032 | C3: 136733 | D3: 119344 | E3: 119344 | F3: 10242 | G3: 0 | H3: 200 | I3: 4102 | J3: 0 | K3: =IFERROR(INDEX('02_Employee_Master'!$D:$D,MATCH(A3,'02_Employee_Master'!$A:$A,0)),"") | L3: =IFERROR(INDEX('02_Employee_Master'!$J:$J,MATCH(A3,'02_Employee_Master'!$A:$A,0)),"")
A4: E003 | B4: C046 | C4: 128298 | D4: 114369 | E4: 114369 | F4: 9880 | G4: 0 | H4: 200 | I4: 3849 | J4: 0 | K4: =IFERROR(INDEX('02_Employee_Master'!$D:$D,MATCH(A4,'02_Employee_Master'!$A:$A,0)),"") | L4: =IFERROR(INDEX('02_Employee_Master'!$J:$J,MATCH(A4,'02_Employee_Master'!$A:$A,0)),"")
A5: E004 | B5: C032 | C5: 63160 | D5: 55497 | E5: 55497 | F5: 4798 | G5: 0 | H5: 200 | I5: 0 | J5: 0 | K5: =IFERROR(INDEX('02_Employee_Master'!$D:$D,MATCH(A5,'02_Employee_Master'!$A:$A,0)),"") | L5: =IFERROR(INDEX('02_Employee_Master'!$J:$J,MATCH(A5,'02_Employee_Master'!$A:$A,0)),"")
A6: E005 | B6: C048 | C6: 75711 | D6: 69367 | E6: 69334 | F6: 6144 | G6: 0 | H6: 200 | I6: 0 | J6: -33 | K6: =IFERROR(INDEX('02_Employee_Master'!$D:$D,MATCH(A6,'02_Employee_Master'!$A:$A,0)),"") | L6: =IFERROR(INDEX('02_Employee_Master'!$J:$J,MATCH(A6,'02_Employee_Master'!$A:$A,0)),"")
A7: E006 | B7: C038 | C7: 93795 | D7: 86214 | E7: 86214 | F7: 7381 | G7: 0 | H7: 200 | I7: 0 | J7: 0 | K7: =IFERROR(INDEX('02_Employee_Master'!$D:$D,MATCH(A7,'02_Employee_Master'!$A:$A,0)),"") | L7: =IFERROR(INDEX('02_Employee_Master'!$J:$J,MATCH(A7,'02_Employee_Master'!$A:$A,0)),"")
A8: E007 | B8: C030 | C8: 54308 | D8: 50020 | E8: 50020 | F8: 4088 | G8: 0 | H8: 200 | I8: 0 | J8: 0 | K8: =IFERROR(INDEX('02_Employee_Master'!$D:$D,MATCH(A8,'02_Employee_Master'!$A:$A,0)),"") | L8: =IFERROR(INDEX('02_Employee_Master'!$J:$J,MATCH(A8,'02_Employee_Master'!$A:$A,0)),"")
A9: E008 | B9: C005 | C9: 78986 | D9: 73260 | E9: 67734 | F9: 5526 | G9: 0 | H9: 200 | I9: 0 | J9: -5526 | K9: =IFERROR(INDEX('02_Employee_Master'!$D:$D,MATCH(A9,'02_Employee_Master'!$A:$A,0)),"") | L9: =IFERROR(INDEX('02_Employee_Master'!$J:$J,MATCH(A9,'02_Employee_Master'!$A:$A,0)),"")
A10: E009 | B10: C012 | C10: 45517 | D10: 42186 | E10: 42186 | F10: 3131 | G10: 0 | H10: 200 | I10: 0 | J10: 0 | K10: =IFERROR(INDEX('02_Employee_Master'!$D:$D,MATCH(A10,'02_Employee_Master'!$A:$A,0)),"") | L10: =IFERROR(INDEX('02_Employee_Master'!$J:$J,MATCH(A10,'02_Employee_Master'!$A:$A,0)),"")
A11: E191 | B11: C030 | C11: 43597 | D11: 40455 | E11: 40455 | F11: 2942 | G11: 0 | H11: 200 | I11: 0 | J11: 0 | K11: =IFERROR(INDEX('02_Employee_Master'!$D:$D,MATCH(A11,'02_Employee_Master'!$A:$A,0)),"") | L11: =IFERROR(INDEX('02_Employee_Master'!$J:$J,MATCH(A11,'02_Employee_Master'!$A:$A,0)),"")
A12: E011 | B12: C009 | C12: 30815 | D12: 28652 | E12: 23568 | F12: 1963 | G12: 0 | H12: 200 | I12: 0 | J12: -5084 | K12: =IFERROR(INDEX('02_Employee_Master'!$D:$D,MATCH(A12,'02_Employee_Master'!$A:$A,0)),"") | L12: =IFERROR(INDEX('02_Employee_Master'!$J:$J,MATCH(A12,'02_Employee_Master'!$A:$A,0)),"")
A13: E012 | B13: C031 | C13: 108998 | D13: 97269 | E13: 97269 | F13: 8259 | G13: 0 | H13: 200 | I13: 3270 | J13: 0 | K13: =IFERROR(INDEX('02_Employee_Master'!$D:$D,MATCH(A13,'02_Employee_Master'!$A:$A,0)),"") | L13: =IFERROR(INDEX('02_Employee_Master'!$J:$J,MATCH(A13,'02_Employee_Master'!$A:$A,0)),"")
... A301: E300 | B301: C010 | C301: 48438 | D301: 44465 | E301: 44465 | F301: 3773 | G301: 0 | H301: 200 | I301: 0 | J301: 0 | K301: =IFERROR(INDEX('02_Employee_Master'!$D:$D,MATCH(A301,'02_Employee_Master'!$A:$A,0)),"") | L301: =IFERROR(INDEX('02_Employee_Master'!$J:$J,MATCH(A301,'02_Employee_Master'!$A:$A,0)),"")

Sheet 04_Task_Pipeline
A1: task_id | B1: customer_id | C1: task_name | D1: owner | E1: due_date | F1: status | G1: company_name
A2: T0001 | B2: C001 | C2: Company Info & KYC | D2: Customer | E2: 46247 | F2: Completed | G2: =IFERROR(INDEX('01_Customer_Tracker'!$B:$B,MATCH(B2,'01_Customer_Tracker'!$A:$A,0)),"")
A3: T0002 | B3: C001 | C3: Document Collection | D3: Customer | E3: 46250 | F3: Completed | G3: =IFERROR(INDEX('01_Customer_Tracker'!$B:$B,MATCH(B3,'01_Customer_Tracker'!$A:$A,0)),"")
A4: T0003 | B4: C001 | C4: Employee Data Upload | D4: Customer | E4: 46254 | F4: Completed | G4: =IFERROR(INDEX('01_Customer_Tracker'!$B:$B,MATCH(B4,'01_Customer_Tracker'!$A:$A,0)),"")
A5: T0004 | B5: C001 | C5: Bank Details Verification | D5: Ops | E5: 46258 | F5: Completed | G5: =IFERROR(INDEX('01_Customer_Tracker'!$B:$B,MATCH(B5,'01_Customer_Tracker'!$A:$A,0)),"")
A6: T0005 | B6: C001 | C6: PAN / UAN Verification | D6: Ops | E6: 46260 | F6: Completed | G6: =IFERROR(INDEX('01_Customer_Tracker'!$B:$B,MATCH(B6,'01_Customer_Tracker'!$A:$A,0)),"")
A7: T0006 | B7: C001 | C7: Attendance & Leave Config | D7: Payroll Ops | E7: 46264 | F7: Completed | G7: =IFERROR(INDEX('01_Customer_Tracker'!$B:$B,MATCH(B7,'01_Customer_Tracker'!$A:$A,0)),"")
A8: T0007 | B8: C001 | C8: Salary Structure Mapping | D8: Payroll Ops | E8: 46267 | F8: Completed | G8: =IFERROR(INDEX('01_Customer_Tracker'!$B:$B,MATCH(B8,'01_Customer_Tracker'!$A:$A,0)),"")
A9: T0008 | B9: C001 | C9: Pre-run Reconciliation | D9: Payroll Ops | E9: 46272 | F9: Completed | G9: =IFERROR(INDEX('01_Customer_Tracker'!$B:$B,MATCH(B9,'01_Customer_Tracker'!$A:$A,0)),"")
A10: T0009 | B10: C001 | C10: Customer Approval Sign-off | D10: Customer | E10: 46276 | F10: Blocked | G10: =IFERROR(INDEX('01_Customer_Tracker'!$B:$B,MATCH(B10,'01_Customer_Tracker'!$A:$A,0)),"")
A11: T0010 | B11: C002 | C11: Company Info & KYC | D11: Customer | E11: 46229 | F11: Completed | G11: =IFERROR(INDEX('01_Customer_Tracker'!$B:$B,MATCH(B11,'01_Customer_Tracker'!$A:$A,0)),"")
A12: T0011 | B12: C002 | C12: Document Collection | D12: Customer | E12: 46232 | F12: Pending | G12: =IFERROR(INDEX('01_Customer_Tracker'!$B:$B,MATCH(B12,'01_Customer_Tracker'!$A:$A,0)),"")
A13: T0012 | B13: C002 | C13: Employee Data Upload | D13: Customer | E13: 46236 | F13: Pending | G13: =IFERROR(INDEX('01_Customer_Tracker'!$B:$B,MATCH(B13,'01_Customer_Tracker'!$A:$A,0)),"")
... A451: T0450 | B451: C050 | C451: Customer Approval Sign-off | D451: Customer | E451: 46274 | F451: Pending | G451: =IFERROR(INDEX('01_Customer_Tracker'!$B:$B,MATCH(B451,'01_Customer_Tracker'!$A:$A,0)),"")

Sheet 05_Exception_Log
A1: customer_id | B1: employee_id | C1: exception_type | D1: severity | E1: recommended_action | F1: company_name
A2: C038 | B2: E006 | C2: Missing UAN | D2: High | E2: Collect UAN or trigger new UAN generation via EPFO portal. | F2: =IFERROR(INDEX('01_Customer_Tracker'!$B:$B,MATCH(A2,'01_Customer_Tracker'!$A:$A,0)),"")
A3: C005 | B3: E008 | C3: Missing Bank Account | D3: Critical | E3: Request updated bank mandate from customer before payroll lock. | F3: =IFERROR(INDEX('01_Customer_Tracker'!$B:$B,MATCH(A3,'01_Customer_Tracker'!$A:$A,0)),"")
A4: C048 | B4: E013 | C4: Missing PAN | D4: High | E4: Collect PAN copy; required for statutory TDS mapping. | F4: =IFERROR(INDEX('01_Customer_Tracker'!$B:$B,MATCH(A4,'01_Customer_Tracker'!$A:$A,0)),"")
A5: C031 | B5: E019 | C5: Missing PAN | D5: High | E5: Collect PAN copy; required for statutory TDS mapping. | F5: =IFERROR(INDEX('01_Customer_Tracker'!$B:$B,MATCH(A5,'01_Customer_Tracker'!$A:$A,0)),"")
A6: C031 | B6: E054 | C6: Zero Attendance Days | D6: Medium | E6: Confirm attendance feed was received for this employee before payroll run. | F6: =IFERROR(INDEX('01_Customer_Tracker'!$B:$B,MATCH(A6,'01_Customer_Tracker'!$A:$A,0)),"")
A7: C030 | B7: E060 | C7: Zero Attendance Days | D7: Medium | E7: Confirm attendance feed was received for this employee before payroll run. | F7: =IFERROR(INDEX('01_Customer_Tracker'!$B:$B,MATCH(A7,'01_Customer_Tracker'!$A:$A,0)),"")
A8: C048 | B8: E069 | C8: Missing Bank Account | D8: Critical | E8: Request updated bank mandate from customer before payroll lock. | F8: =IFERROR(INDEX('01_Customer_Tracker'!$B:$B,MATCH(A8,'01_Customer_Tracker'!$A:$A,0)),"")
A9: C023 | B9: E071 | C9: Overtime Outlier (>50% of Basic) | D9: Medium | E9: Escalate to customer for overtime approval before disbursal. | F9: =IFERROR(INDEX('01_Customer_Tracker'!$B:$B,MATCH(A9,'01_Customer_Tracker'!$A:$A,0)),"")
A10: C035 | B10: E083 | C10: Missing UAN | D10: High | E10: Collect UAN or trigger new UAN generation via EPFO portal. | F10: =IFERROR(INDEX('01_Customer_Tracker'!$B:$B,MATCH(A10,'01_Customer_Tracker'!$A:$A,0)),"")
A11: C007 | B11: E107 | C11: Missing Bank Account | D11: Critical | E11: Request updated bank mandate from customer before payroll lock. | F11: =IFERROR(INDEX('01_Customer_Tracker'!$B:$B,MATCH(A11,'01_Customer_Tracker'!$A:$A,0)),"")
A12: C027 | B12: E110 | C12: Invalid Bank Account Format | D12: Critical | E12: Re-verify account number with customer HR/finance POC. | F12: =IFERROR(INDEX('01_Customer_Tracker'!$B:$B,MATCH(A12,'01_Customer_Tracker'!$A:$A,0)),"")
A13: C041 | B13: E115 | C13: Missing UAN | D13: High | E13: Collect UAN or trigger new UAN generation via EPFO portal. | F13: =IFERROR(INDEX('01_Customer_Tracker'!$B:$B,MATCH(A13,'01_Customer_Tracker'!$A:$A,0)),"")
... A41: C033 | B41: E178 | C41: Duplicate Employee ID | D41: Critical | E41: Reissue a unique employee ID; duplicate IDs will corrupt payroll register keys. | F41: =IFERROR(INDEX('01_Customer_Tracker'!$B:$B,MATCH(A41,'01_Customer_Tracker'!$A:$A,0)),"")

Sheet 06_Reconciliation_Summary
A1: customer_id | B1: company_name | C1: expected_gross | D1: expected_net | E1: processed_net | F1: variance | G1: reconciliation_status | H1: sumifs_expected_net_check | I1: sumifs_processed_net_check
A2: C001 | B2: =IFERROR(INDEX('01_Customer_Tracker'!$B:$B,MATCH(A2,'01_Customer_Tracker'!$A:$A,0)),"") | C2: 203302 | D2: 187507 | E2: 187507 | F2: 0 | G2: Reconciled | H2: =SUMIFS('03_Payroll_Register'!$D:$D,'03_Payroll_Register'!$B:$B,A2) | I2: =SUMIFS('03_Payroll_Register'!$E:$E,'03_Payroll_Register'!$B:$B,A2)
A3: C002 | B3: =IFERROR(INDEX('01_Customer_Tracker'!$B:$B,MATCH(A3,'01_Customer_Tracker'!$A:$A,0)),"") | C3: 610706 | D3: 559868 | E3: 559868 | F3: 0 | G3: Reconciled | H3: =SUMIFS('03_Payroll_Register'!$D:$D,'03_Payroll_Register'!$B:$B,A3) | I3: =SUMIFS('03_Payroll_Register'!$E:$E,'03_Payroll_Register'!$B:$B,A3)
A4: C003 | B4: =IFERROR(INDEX('01_Customer_Tracker'!$B:$B,MATCH(A4,'01_Customer_Tracker'!$A:$A,0)),"") | C4: 884519 | D4: 790818 | E4: 790818 | F4: 0 | G4: Reconciled | H4: =SUMIFS('03_Payroll_Register'!$D:$D,'03_Payroll_Register'!$B:$B,A4) | I4: =SUMIFS('03_Payroll_Register'!$E:$E,'03_Payroll_Register'!$B:$B,A4)
A5: C004 | B5: =IFERROR(INDEX('01_Customer_Tracker'!$B:$B,MATCH(A5,'01_Customer_Tracker'!$A:$A,0)),"") | C5: 325535 | D5: 296204 | E5: 296204 | F5: 0 | G5: Reconciled | H5: =SUMIFS('03_Payroll_Register'!$D:$D,'03_Payroll_Register'!$B:$B,A5) | I5: =SUMIFS('03_Payroll_Register'!$E:$E,'03_Payroll_Register'!$B:$B,A5)
A6: C005 | B6: =IFERROR(INDEX('01_Customer_Tracker'!$B:$B,MATCH(A6,'01_Customer_Tracker'!$A:$A,0)),"") | C6: 1186939 | D6: 1076239 | E6: 987007 | F6: -89232 | G6: Unreconciled | H6: =SUMIFS('03_Payroll_Register'!$D:$D,'03_Payroll_Register'!$B:$B,A6) | I6: =SUMIFS('03_Payroll_Register'!$E:$E,'03_Payroll_Register'!$B:$B,A6)
A7: C006 | B7: =IFERROR(INDEX('01_Customer_Tracker'!$B:$B,MATCH(A7,'01_Customer_Tracker'!$A:$A,0)),"") | C7: 1115311 | D7: 1003597 | E7: 1002874 | F7: -723 | G7: Unreconciled | H7: =SUMIFS('03_Payroll_Register'!$D:$D,'03_Payroll_Register'!$B:$B,A7) | I7: =SUMIFS('03_Payroll_Register'!$E:$E,'03_Payroll_Register'!$B:$B,A7)
A8: C007 | B8: =IFERROR(INDEX('01_Customer_Tracker'!$B:$B,MATCH(A8,'01_Customer_Tracker'!$A:$A,0)),"") | C8: 832957 | D8: 740009 | E8: 740009 | F8: 0 | G8: Reconciled | H8: =SUMIFS('03_Payroll_Register'!$D:$D,'03_Payroll_Register'!$B:$B,A8) | I8: =SUMIFS('03_Payroll_Register'!$E:$E,'03_Payroll_Register'!$B:$B,A8)
A9: C008 | B9: =IFERROR(INDEX('01_Customer_Tracker'!$B:$B,MATCH(A9,'01_Customer_Tracker'!$A:$A,0)),"") | C9: 350406 | D9: 314162 | E9: 314162 | F9: 0 | G9: Reconciled | H9: =SUMIFS('03_Payroll_Register'!$D:$D,'03_Payroll_Register'!$B:$B,A9) | I9: =SUMIFS('03_Payroll_Register'!$E:$E,'03_Payroll_Register'!$B:$B,A9)
A10: C009 | B10: =IFERROR(INDEX('01_Customer_Tracker'!$B:$B,MATCH(A10,'01_Customer_Tracker'!$A:$A,0)),"") | C10: 232314 | D10: 211011 | E10: 199521 | F10: -11490 | G10: Unreconciled | H10: =SUMIFS('03_Payroll_Register'!$D:$D,'03_Payroll_Register'!$B:$B,A10) | I10: =SUMIFS('03_Payroll_Register'!$E:$E,'03_Payroll_Register'!$B:$B,A10)
A11: C010 | B11: =IFERROR(INDEX('01_Customer_Tracker'!$B:$B,MATCH(A11,'01_Customer_Tracker'!$A:$A,0)),"") | C11: 245610 | D11: 222375 | E11: 222375 | F11: 0 | G11: Reconciled | H11: =SUMIFS('03_Payroll_Register'!$D:$D,'03_Payroll_Register'!$B:$B,A11) | I11: =SUMIFS('03_Payroll_Register'!$E:$E,'03_Payroll_Register'!$B:$B,A11)
A12: C011 | B12: =IFERROR(INDEX('01_Customer_Tracker'!$B:$B,MATCH(A12,'01_Customer_Tracker'!$A:$A,0)),"") | C12: 194043 | D12: 178801 | E12: 178801 | F12: 0 | G12: Reconciled | H12: =SUMIFS('03_Payroll_Register'!$D:$D,'03_Payroll_Register'!$B:$B,A12) | I12: =SUMIFS('03_Payroll_Register'!$E:$E,'03_Payroll_Register'!$B:$B,A12)
A13: C012 | B13: =IFERROR(INDEX('01_Customer_Tracker'!$B:$B,MATCH(A13,'01_Customer_Tracker'!$A:$A,0)),"") | C13: 841107 | D13: 762183 | E13: 762183 | F13: 0 | G13: Reconciled | H13: =SUMIFS('03_Payroll_Register'!$D:$D,'03_Payroll_Register'!$B:$B,A13) | I13: =SUMIFS('03_Payroll_Register'!$E:$E,'03_Payroll_Register'!$B:$B,A13)
... A51: C050 | B51: =IFERROR(INDEX('01_Customer_Tracker'!$B:$B,MATCH(A51,'01_Customer_Tracker'!$A:$A,0)),"") | C51: 486308 | D51: 442462 | E51: 442462 | F51: 0 | G51: Reconciled | H51: =SUMIFS('03_Payroll_Register'!$D:$D,'03_Payroll_Register'!$B:$B,A51) | I51: =SUMIFS('03_Payroll_Register'!$E:$E,'03_Payroll_Register'!$B:$B,A51)

Sheet 07_KPI_Dashboard
B2: PayFlow — Payroll Operations KPI Dashboard
B4: Onboarding Pipeline
B5: Total Onboarding Accounts | C5: =COUNTA('01_Customer_Tracker'!$A$2:$A$51)
B6: On Track | C6: =COUNTIF('01_Customer_Tracker'!$H:$H,"On Track")
B7: At Risk | C7: =COUNTIF('01_Customer_Tracker'!$H:$H,"At Risk")
B8: Blocked | C8: =COUNTIF('01_Customer_Tracker'!$H:$H,"Blocked")
B9: Completed | C9: =COUNTIF('01_Customer_Tracker'!$H:$H,"Completed")
B10: SLA Breach (recomputed) | C10: =COUNTIF('01_Customer_Tracker'!$N:$N,"SLA Breach")
B11: Average Task Completion % | C11: =AVERAGE('01_Customer_Tracker'!$K:$K)
B13: Payroll Reconciliation
B14: Reconciled Accounts | C14: =COUNTIF('06_Reconciliation_Summary'!$G:$G,"Reconciled")
B15: Under Review | C15: =COUNTIF('06_Reconciliation_Summary'!$G:$G,"Under Review")
B16: Unreconciled | C16: =COUNTIF('06_Reconciliation_Summary'!$G:$G,"Unreconciled")
B17: Total Expected Gross (₹) | C17: =SUM('06_Reconciliation_Summary'!$C:$C)
B18: Total Expected Net (₹) | C18: =SUM('06_Reconciliation_Summary'!$D:$D)
B19: Total Processed Net (₹) | C19: =SUM('06_Reconciliation_Summary'!$E:$E)
B20: Total Net Variance (₹) | C20: =SUM('06_Reconciliation_Summary'!$F:$F)
B22: Exception Severity
B23: Critical Exceptions | C23: =COUNTIF('05_Exception_Log'!$D:$D,"Critical")
B24: High Exceptions | C24: =COUNTIF('05_Exception_Log'!$D:$D,"High")
B25: Medium Exceptions | C25: =COUNTIF('05_Exception_Log'!$D:$D,"Medium")
B26: Total Exceptions Logged | C26: =COUNTA('05_Exception_Log'!$A$2:$A$100000)
